<?xml version="1.0"?>
<robot name="single_link_arm">
<link name="world">
</link>

<!-- <link name="Motor">
        <visual>
            <origin rpy="0 0.0 0" xyz="0 0 0"/>
            <geometry>
                <mesh filename="package://mini_challenge_2/models/motor_STL.stl"/>
            </geometry>
        </visual>
</link> -->

<link name="Wheel">
        <visual>
            <origin rpy="0 0 0" xyz="0 0.0 0"/>
            <geometry>
                <mesh filename="package://mini_challenge_2/models/MCR2_1000_1_1_Wheel_Coupler_2.stl"/>
            </geometry>
        </visual>
</link>

<!-- <joint name="joint1" type="fixed">
    <origin xyz="0 0 1" rpy="0 0 0" />
    <parent link="world" />
    <child link="Motor" />
</joint> -->

<joint name="joint2" type="continuous">
    <origin xyz="0.041475 0 0" rpy="0 0 0" />
    <parent link="world" />
    <child link="Wheel" />
    <axis xyz="1 0 0" />
</joint>

</robot>